exception foo

try {
    throw foo 
} catch (foo) {
    2
}